[2023-06-17T05:50:56.605+0000] {processor.py:157} INFO - Started process (PID=46) to work on /opt/airflow/dags/sql/load_dag.py
[2023-06-17T05:50:56.606+0000] {processor.py:826} INFO - Processing file /opt/airflow/dags/sql/load_dag.py for tasks to queue
[2023-06-17T05:50:56.607+0000] {logging_mixin.py:149} INFO - [2023-06-17T05:50:56.607+0000] {dagbag.py:541} INFO - Filling up the DagBag from /opt/airflow/dags/sql/load_dag.py
[2023-06-17T05:50:57.387+0000] {logging_mixin.py:149} INFO - [2023-06-17T05:50:57.362+0000] {dagbag.py:447} ERROR - Failed to bag_dag: /opt/airflow/dags/sql/load_dag.py
Traceback (most recent call last):
  File "/home/airflow/.local/lib/python3.7/site-packages/airflow/models/dagbag.py", line 445, in _process_modules
    self.bag_dag(dag=dag, root_dag=dag)
  File "/home/airflow/.local/lib/python3.7/site-packages/airflow/models/dagbag.py", line 462, in bag_dag
    self._bag_dag(dag=dag, root_dag=root_dag, recursive=True)
  File "/home/airflow/.local/lib/python3.7/site-packages/airflow/models/dagbag.py", line 470, in _bag_dag
    check_cycle(dag)  # throws if a task cycle is found
  File "/home/airflow/.local/lib/python3.7/site-packages/airflow/utils/dag_cycle_tester.py", line 78, in check_cycle
    child_to_check = _check_adjacent_tasks(current_task_id, task)
  File "/home/airflow/.local/lib/python3.7/site-packages/airflow/utils/dag_cycle_tester.py", line 64, in _check_adjacent_tasks
    raise AirflowDagCycleException(msg)
airflow.exceptions.AirflowDagCycleException: Cycle detected in DAG: load-data. Faulty task: create_shipment_deliveries
[2023-06-17T05:50:57.387+0000] {processor.py:838} WARNING - No viable dags retrieved from /opt/airflow/dags/sql/load_dag.py
[2023-06-17T05:50:57.536+0000] {processor.py:179} INFO - Processing /opt/airflow/dags/sql/load_dag.py took 0.934 seconds
[2023-06-17T05:51:28.344+0000] {processor.py:157} INFO - Started process (PID=112) to work on /opt/airflow/dags/sql/load_dag.py
[2023-06-17T05:51:28.345+0000] {processor.py:826} INFO - Processing file /opt/airflow/dags/sql/load_dag.py for tasks to queue
[2023-06-17T05:51:28.347+0000] {logging_mixin.py:149} INFO - [2023-06-17T05:51:28.346+0000] {dagbag.py:541} INFO - Filling up the DagBag from /opt/airflow/dags/sql/load_dag.py
[2023-06-17T05:51:28.594+0000] {logging_mixin.py:149} INFO - [2023-06-17T05:51:28.554+0000] {dagbag.py:447} ERROR - Failed to bag_dag: /opt/airflow/dags/sql/load_dag.py
Traceback (most recent call last):
  File "/home/airflow/.local/lib/python3.7/site-packages/airflow/models/dagbag.py", line 445, in _process_modules
    self.bag_dag(dag=dag, root_dag=dag)
  File "/home/airflow/.local/lib/python3.7/site-packages/airflow/models/dagbag.py", line 462, in bag_dag
    self._bag_dag(dag=dag, root_dag=root_dag, recursive=True)
  File "/home/airflow/.local/lib/python3.7/site-packages/airflow/models/dagbag.py", line 470, in _bag_dag
    check_cycle(dag)  # throws if a task cycle is found
  File "/home/airflow/.local/lib/python3.7/site-packages/airflow/utils/dag_cycle_tester.py", line 78, in check_cycle
    child_to_check = _check_adjacent_tasks(current_task_id, task)
  File "/home/airflow/.local/lib/python3.7/site-packages/airflow/utils/dag_cycle_tester.py", line 64, in _check_adjacent_tasks
    raise AirflowDagCycleException(msg)
airflow.exceptions.AirflowDagCycleException: Cycle detected in DAG: load-data. Faulty task: create_shipment_deliveries
[2023-06-17T05:51:28.595+0000] {processor.py:838} WARNING - No viable dags retrieved from /opt/airflow/dags/sql/load_dag.py
[2023-06-17T05:51:28.754+0000] {processor.py:179} INFO - Processing /opt/airflow/dags/sql/load_dag.py took 0.419 seconds
[2023-06-17T05:51:59.719+0000] {processor.py:157} INFO - Started process (PID=175) to work on /opt/airflow/dags/sql/load_dag.py
[2023-06-17T05:51:59.741+0000] {processor.py:826} INFO - Processing file /opt/airflow/dags/sql/load_dag.py for tasks to queue
[2023-06-17T05:51:59.744+0000] {logging_mixin.py:149} INFO - [2023-06-17T05:51:59.744+0000] {dagbag.py:541} INFO - Filling up the DagBag from /opt/airflow/dags/sql/load_dag.py
[2023-06-17T05:51:59.771+0000] {logging_mixin.py:149} INFO - [2023-06-17T05:51:59.770+0000] {dagbag.py:447} ERROR - Failed to bag_dag: /opt/airflow/dags/sql/load_dag.py
Traceback (most recent call last):
  File "/home/airflow/.local/lib/python3.7/site-packages/airflow/models/dagbag.py", line 445, in _process_modules
    self.bag_dag(dag=dag, root_dag=dag)
  File "/home/airflow/.local/lib/python3.7/site-packages/airflow/models/dagbag.py", line 462, in bag_dag
    self._bag_dag(dag=dag, root_dag=root_dag, recursive=True)
  File "/home/airflow/.local/lib/python3.7/site-packages/airflow/models/dagbag.py", line 470, in _bag_dag
    check_cycle(dag)  # throws if a task cycle is found
  File "/home/airflow/.local/lib/python3.7/site-packages/airflow/utils/dag_cycle_tester.py", line 78, in check_cycle
    child_to_check = _check_adjacent_tasks(current_task_id, task)
  File "/home/airflow/.local/lib/python3.7/site-packages/airflow/utils/dag_cycle_tester.py", line 64, in _check_adjacent_tasks
    raise AirflowDagCycleException(msg)
airflow.exceptions.AirflowDagCycleException: Cycle detected in DAG: load-data. Faulty task: create_shipment_deliveries
[2023-06-17T05:51:59.772+0000] {processor.py:838} WARNING - No viable dags retrieved from /opt/airflow/dags/sql/load_dag.py
[2023-06-17T05:51:59.874+0000] {processor.py:179} INFO - Processing /opt/airflow/dags/sql/load_dag.py took 0.161 seconds
[2023-06-17T05:52:31.016+0000] {processor.py:157} INFO - Started process (PID=217) to work on /opt/airflow/dags/sql/load_dag.py
[2023-06-17T05:52:31.017+0000] {processor.py:826} INFO - Processing file /opt/airflow/dags/sql/load_dag.py for tasks to queue
[2023-06-17T05:52:31.018+0000] {logging_mixin.py:149} INFO - [2023-06-17T05:52:31.018+0000] {dagbag.py:541} INFO - Filling up the DagBag from /opt/airflow/dags/sql/load_dag.py
[2023-06-17T05:52:31.031+0000] {logging_mixin.py:149} INFO - [2023-06-17T05:52:31.030+0000] {dagbag.py:447} ERROR - Failed to bag_dag: /opt/airflow/dags/sql/load_dag.py
Traceback (most recent call last):
  File "/home/airflow/.local/lib/python3.7/site-packages/airflow/models/dagbag.py", line 445, in _process_modules
    self.bag_dag(dag=dag, root_dag=dag)
  File "/home/airflow/.local/lib/python3.7/site-packages/airflow/models/dagbag.py", line 462, in bag_dag
    self._bag_dag(dag=dag, root_dag=root_dag, recursive=True)
  File "/home/airflow/.local/lib/python3.7/site-packages/airflow/models/dagbag.py", line 470, in _bag_dag
    check_cycle(dag)  # throws if a task cycle is found
  File "/home/airflow/.local/lib/python3.7/site-packages/airflow/utils/dag_cycle_tester.py", line 78, in check_cycle
    child_to_check = _check_adjacent_tasks(current_task_id, task)
  File "/home/airflow/.local/lib/python3.7/site-packages/airflow/utils/dag_cycle_tester.py", line 64, in _check_adjacent_tasks
    raise AirflowDagCycleException(msg)
airflow.exceptions.AirflowDagCycleException: Cycle detected in DAG: load-data. Faulty task: create_shipment_deliveries
[2023-06-17T05:52:31.031+0000] {processor.py:838} WARNING - No viable dags retrieved from /opt/airflow/dags/sql/load_dag.py
[2023-06-17T05:52:31.213+0000] {processor.py:179} INFO - Processing /opt/airflow/dags/sql/load_dag.py took 0.202 seconds
[2023-06-17T05:53:01.668+0000] {processor.py:157} INFO - Started process (PID=282) to work on /opt/airflow/dags/sql/load_dag.py
[2023-06-17T05:53:01.669+0000] {processor.py:826} INFO - Processing file /opt/airflow/dags/sql/load_dag.py for tasks to queue
[2023-06-17T05:53:01.670+0000] {logging_mixin.py:149} INFO - [2023-06-17T05:53:01.670+0000] {dagbag.py:541} INFO - Filling up the DagBag from /opt/airflow/dags/sql/load_dag.py
[2023-06-17T05:53:01.681+0000] {logging_mixin.py:149} INFO - [2023-06-17T05:53:01.680+0000] {dagbag.py:447} ERROR - Failed to bag_dag: /opt/airflow/dags/sql/load_dag.py
Traceback (most recent call last):
  File "/home/airflow/.local/lib/python3.7/site-packages/airflow/models/dagbag.py", line 445, in _process_modules
    self.bag_dag(dag=dag, root_dag=dag)
  File "/home/airflow/.local/lib/python3.7/site-packages/airflow/models/dagbag.py", line 462, in bag_dag
    self._bag_dag(dag=dag, root_dag=root_dag, recursive=True)
  File "/home/airflow/.local/lib/python3.7/site-packages/airflow/models/dagbag.py", line 470, in _bag_dag
    check_cycle(dag)  # throws if a task cycle is found
  File "/home/airflow/.local/lib/python3.7/site-packages/airflow/utils/dag_cycle_tester.py", line 78, in check_cycle
    child_to_check = _check_adjacent_tasks(current_task_id, task)
  File "/home/airflow/.local/lib/python3.7/site-packages/airflow/utils/dag_cycle_tester.py", line 64, in _check_adjacent_tasks
    raise AirflowDagCycleException(msg)
airflow.exceptions.AirflowDagCycleException: Cycle detected in DAG: load-data. Faulty task: create_shipment_deliveries
[2023-06-17T05:53:01.681+0000] {processor.py:838} WARNING - No viable dags retrieved from /opt/airflow/dags/sql/load_dag.py
[2023-06-17T05:53:01.723+0000] {processor.py:179} INFO - Processing /opt/airflow/dags/sql/load_dag.py took 0.059 seconds
[2023-06-17T05:53:32.520+0000] {processor.py:157} INFO - Started process (PID=350) to work on /opt/airflow/dags/sql/load_dag.py
[2023-06-17T05:53:32.523+0000] {processor.py:826} INFO - Processing file /opt/airflow/dags/sql/load_dag.py for tasks to queue
[2023-06-17T05:53:32.527+0000] {logging_mixin.py:149} INFO - [2023-06-17T05:53:32.526+0000] {dagbag.py:541} INFO - Filling up the DagBag from /opt/airflow/dags/sql/load_dag.py
[2023-06-17T05:53:32.553+0000] {logging_mixin.py:149} INFO - [2023-06-17T05:53:32.551+0000] {dagbag.py:447} ERROR - Failed to bag_dag: /opt/airflow/dags/sql/load_dag.py
Traceback (most recent call last):
  File "/home/airflow/.local/lib/python3.7/site-packages/airflow/models/dagbag.py", line 445, in _process_modules
    self.bag_dag(dag=dag, root_dag=dag)
  File "/home/airflow/.local/lib/python3.7/site-packages/airflow/models/dagbag.py", line 462, in bag_dag
    self._bag_dag(dag=dag, root_dag=root_dag, recursive=True)
  File "/home/airflow/.local/lib/python3.7/site-packages/airflow/models/dagbag.py", line 470, in _bag_dag
    check_cycle(dag)  # throws if a task cycle is found
  File "/home/airflow/.local/lib/python3.7/site-packages/airflow/utils/dag_cycle_tester.py", line 78, in check_cycle
    child_to_check = _check_adjacent_tasks(current_task_id, task)
  File "/home/airflow/.local/lib/python3.7/site-packages/airflow/utils/dag_cycle_tester.py", line 64, in _check_adjacent_tasks
    raise AirflowDagCycleException(msg)
airflow.exceptions.AirflowDagCycleException: Cycle detected in DAG: load-data. Faulty task: create_shipment_deliveries
[2023-06-17T05:53:32.553+0000] {processor.py:838} WARNING - No viable dags retrieved from /opt/airflow/dags/sql/load_dag.py
[2023-06-17T05:53:32.597+0000] {processor.py:179} INFO - Processing /opt/airflow/dags/sql/load_dag.py took 0.091 seconds
[2023-06-17T05:54:02.977+0000] {processor.py:157} INFO - Started process (PID=418) to work on /opt/airflow/dags/sql/load_dag.py
[2023-06-17T05:54:03.003+0000] {processor.py:826} INFO - Processing file /opt/airflow/dags/sql/load_dag.py for tasks to queue
[2023-06-17T05:54:03.004+0000] {logging_mixin.py:149} INFO - [2023-06-17T05:54:03.004+0000] {dagbag.py:541} INFO - Filling up the DagBag from /opt/airflow/dags/sql/load_dag.py
[2023-06-17T05:54:03.016+0000] {logging_mixin.py:149} INFO - [2023-06-17T05:54:03.015+0000] {dagbag.py:447} ERROR - Failed to bag_dag: /opt/airflow/dags/sql/load_dag.py
Traceback (most recent call last):
  File "/home/airflow/.local/lib/python3.7/site-packages/airflow/models/dagbag.py", line 445, in _process_modules
    self.bag_dag(dag=dag, root_dag=dag)
  File "/home/airflow/.local/lib/python3.7/site-packages/airflow/models/dagbag.py", line 462, in bag_dag
    self._bag_dag(dag=dag, root_dag=root_dag, recursive=True)
  File "/home/airflow/.local/lib/python3.7/site-packages/airflow/models/dagbag.py", line 470, in _bag_dag
    check_cycle(dag)  # throws if a task cycle is found
  File "/home/airflow/.local/lib/python3.7/site-packages/airflow/utils/dag_cycle_tester.py", line 78, in check_cycle
    child_to_check = _check_adjacent_tasks(current_task_id, task)
  File "/home/airflow/.local/lib/python3.7/site-packages/airflow/utils/dag_cycle_tester.py", line 64, in _check_adjacent_tasks
    raise AirflowDagCycleException(msg)
airflow.exceptions.AirflowDagCycleException: Cycle detected in DAG: load-data. Faulty task: create_shipment_deliveries
[2023-06-17T05:54:03.016+0000] {processor.py:838} WARNING - No viable dags retrieved from /opt/airflow/dags/sql/load_dag.py
[2023-06-17T05:54:03.102+0000] {processor.py:179} INFO - Processing /opt/airflow/dags/sql/load_dag.py took 0.132 seconds
[2023-06-17T05:54:37.383+0000] {processor.py:157} INFO - Started process (PID=479) to work on /opt/airflow/dags/sql/load_dag.py
[2023-06-17T05:54:37.483+0000] {processor.py:826} INFO - Processing file /opt/airflow/dags/sql/load_dag.py for tasks to queue
[2023-06-17T05:54:37.484+0000] {logging_mixin.py:149} INFO - [2023-06-17T05:54:37.484+0000] {dagbag.py:541} INFO - Filling up the DagBag from /opt/airflow/dags/sql/load_dag.py
[2023-06-17T05:54:40.209+0000] {logging_mixin.py:149} INFO - [2023-06-17T05:54:39.636+0000] {dagbag.py:447} ERROR - Failed to bag_dag: /opt/airflow/dags/sql/load_dag.py
Traceback (most recent call last):
  File "/home/airflow/.local/lib/python3.7/site-packages/airflow/models/dagbag.py", line 445, in _process_modules
    self.bag_dag(dag=dag, root_dag=dag)
  File "/home/airflow/.local/lib/python3.7/site-packages/airflow/models/dagbag.py", line 462, in bag_dag
    self._bag_dag(dag=dag, root_dag=root_dag, recursive=True)
  File "/home/airflow/.local/lib/python3.7/site-packages/airflow/models/dagbag.py", line 470, in _bag_dag
    check_cycle(dag)  # throws if a task cycle is found
  File "/home/airflow/.local/lib/python3.7/site-packages/airflow/utils/dag_cycle_tester.py", line 78, in check_cycle
    child_to_check = _check_adjacent_tasks(current_task_id, task)
  File "/home/airflow/.local/lib/python3.7/site-packages/airflow/utils/dag_cycle_tester.py", line 64, in _check_adjacent_tasks
    raise AirflowDagCycleException(msg)
airflow.exceptions.AirflowDagCycleException: Cycle detected in DAG: load-data. Faulty task: create_shipment_deliveries
[2023-06-17T05:54:40.210+0000] {processor.py:838} WARNING - No viable dags retrieved from /opt/airflow/dags/sql/load_dag.py
[2023-06-17T05:54:40.466+0000] {processor.py:179} INFO - Processing /opt/airflow/dags/sql/load_dag.py took 3.091 seconds
[2023-06-17T05:55:10.742+0000] {processor.py:157} INFO - Started process (PID=543) to work on /opt/airflow/dags/sql/load_dag.py
[2023-06-17T05:55:10.842+0000] {processor.py:826} INFO - Processing file /opt/airflow/dags/sql/load_dag.py for tasks to queue
[2023-06-17T05:55:10.845+0000] {logging_mixin.py:149} INFO - [2023-06-17T05:55:10.844+0000] {dagbag.py:541} INFO - Filling up the DagBag from /opt/airflow/dags/sql/load_dag.py
[2023-06-17T05:55:10.878+0000] {logging_mixin.py:149} INFO - [2023-06-17T05:55:10.876+0000] {dagbag.py:447} ERROR - Failed to bag_dag: /opt/airflow/dags/sql/load_dag.py
Traceback (most recent call last):
  File "/home/airflow/.local/lib/python3.7/site-packages/airflow/models/dagbag.py", line 445, in _process_modules
    self.bag_dag(dag=dag, root_dag=dag)
  File "/home/airflow/.local/lib/python3.7/site-packages/airflow/models/dagbag.py", line 462, in bag_dag
    self._bag_dag(dag=dag, root_dag=root_dag, recursive=True)
  File "/home/airflow/.local/lib/python3.7/site-packages/airflow/models/dagbag.py", line 470, in _bag_dag
    check_cycle(dag)  # throws if a task cycle is found
  File "/home/airflow/.local/lib/python3.7/site-packages/airflow/utils/dag_cycle_tester.py", line 78, in check_cycle
    child_to_check = _check_adjacent_tasks(current_task_id, task)
  File "/home/airflow/.local/lib/python3.7/site-packages/airflow/utils/dag_cycle_tester.py", line 64, in _check_adjacent_tasks
    raise AirflowDagCycleException(msg)
airflow.exceptions.AirflowDagCycleException: Cycle detected in DAG: load-data. Faulty task: create_shipment_deliveries
[2023-06-17T05:55:10.879+0000] {processor.py:838} WARNING - No viable dags retrieved from /opt/airflow/dags/sql/load_dag.py
[2023-06-17T05:55:10.953+0000] {processor.py:179} INFO - Processing /opt/airflow/dags/sql/load_dag.py took 0.217 seconds
[2023-06-17T05:55:41.161+0000] {processor.py:157} INFO - Started process (PID=611) to work on /opt/airflow/dags/sql/load_dag.py
[2023-06-17T05:55:41.204+0000] {processor.py:826} INFO - Processing file /opt/airflow/dags/sql/load_dag.py for tasks to queue
[2023-06-17T05:55:41.205+0000] {logging_mixin.py:149} INFO - [2023-06-17T05:55:41.205+0000] {dagbag.py:541} INFO - Filling up the DagBag from /opt/airflow/dags/sql/load_dag.py
[2023-06-17T05:55:41.217+0000] {logging_mixin.py:149} INFO - [2023-06-17T05:55:41.215+0000] {dagbag.py:447} ERROR - Failed to bag_dag: /opt/airflow/dags/sql/load_dag.py
Traceback (most recent call last):
  File "/home/airflow/.local/lib/python3.7/site-packages/airflow/models/dagbag.py", line 445, in _process_modules
    self.bag_dag(dag=dag, root_dag=dag)
  File "/home/airflow/.local/lib/python3.7/site-packages/airflow/models/dagbag.py", line 462, in bag_dag
    self._bag_dag(dag=dag, root_dag=root_dag, recursive=True)
  File "/home/airflow/.local/lib/python3.7/site-packages/airflow/models/dagbag.py", line 470, in _bag_dag
    check_cycle(dag)  # throws if a task cycle is found
  File "/home/airflow/.local/lib/python3.7/site-packages/airflow/utils/dag_cycle_tester.py", line 78, in check_cycle
    child_to_check = _check_adjacent_tasks(current_task_id, task)
  File "/home/airflow/.local/lib/python3.7/site-packages/airflow/utils/dag_cycle_tester.py", line 64, in _check_adjacent_tasks
    raise AirflowDagCycleException(msg)
airflow.exceptions.AirflowDagCycleException: Cycle detected in DAG: load-data. Faulty task: create_shipment_deliveries
[2023-06-17T05:55:41.217+0000] {processor.py:838} WARNING - No viable dags retrieved from /opt/airflow/dags/sql/load_dag.py
[2023-06-17T05:55:41.288+0000] {processor.py:179} INFO - Processing /opt/airflow/dags/sql/load_dag.py took 0.131 seconds
[2023-06-17T14:09:10.386+0000] {processor.py:157} INFO - Started process (PID=55) to work on /opt/airflow/dags/sql/load_dag.py
[2023-06-17T14:09:10.424+0000] {processor.py:826} INFO - Processing file /opt/airflow/dags/sql/load_dag.py for tasks to queue
[2023-06-17T14:09:10.425+0000] {logging_mixin.py:149} INFO - [2023-06-17T14:09:10.425+0000] {dagbag.py:541} INFO - Filling up the DagBag from /opt/airflow/dags/sql/load_dag.py
[2023-06-17T14:09:11.169+0000] {logging_mixin.py:149} INFO - [2023-06-17T14:09:11.111+0000] {dagbag.py:447} ERROR - Failed to bag_dag: /opt/airflow/dags/sql/load_dag.py
Traceback (most recent call last):
  File "/home/airflow/.local/lib/python3.7/site-packages/airflow/models/dagbag.py", line 445, in _process_modules
    self.bag_dag(dag=dag, root_dag=dag)
  File "/home/airflow/.local/lib/python3.7/site-packages/airflow/models/dagbag.py", line 462, in bag_dag
    self._bag_dag(dag=dag, root_dag=root_dag, recursive=True)
  File "/home/airflow/.local/lib/python3.7/site-packages/airflow/models/dagbag.py", line 470, in _bag_dag
    check_cycle(dag)  # throws if a task cycle is found
  File "/home/airflow/.local/lib/python3.7/site-packages/airflow/utils/dag_cycle_tester.py", line 78, in check_cycle
    child_to_check = _check_adjacent_tasks(current_task_id, task)
  File "/home/airflow/.local/lib/python3.7/site-packages/airflow/utils/dag_cycle_tester.py", line 64, in _check_adjacent_tasks
    raise AirflowDagCycleException(msg)
airflow.exceptions.AirflowDagCycleException: Cycle detected in DAG: load-data. Faulty task: create_shipment_deliveries
[2023-06-17T14:09:11.169+0000] {processor.py:838} WARNING - No viable dags retrieved from /opt/airflow/dags/sql/load_dag.py
[2023-06-17T14:09:11.313+0000] {processor.py:179} INFO - Processing /opt/airflow/dags/sql/load_dag.py took 0.932 seconds
[2023-06-17T14:10:00.109+0000] {processor.py:157} INFO - Started process (PID=122) to work on /opt/airflow/dags/sql/load_dag.py
[2023-06-17T14:10:00.252+0000] {processor.py:826} INFO - Processing file /opt/airflow/dags/sql/load_dag.py for tasks to queue
[2023-06-17T14:10:00.254+0000] {logging_mixin.py:149} INFO - [2023-06-17T14:10:00.253+0000] {dagbag.py:541} INFO - Filling up the DagBag from /opt/airflow/dags/sql/load_dag.py
[2023-06-17T14:10:00.415+0000] {logging_mixin.py:149} INFO - [2023-06-17T14:10:00.363+0000] {dagbag.py:447} ERROR - Failed to bag_dag: /opt/airflow/dags/sql/load_dag.py
Traceback (most recent call last):
  File "/home/airflow/.local/lib/python3.7/site-packages/airflow/models/dagbag.py", line 445, in _process_modules
    self.bag_dag(dag=dag, root_dag=dag)
  File "/home/airflow/.local/lib/python3.7/site-packages/airflow/models/dagbag.py", line 462, in bag_dag
    self._bag_dag(dag=dag, root_dag=root_dag, recursive=True)
  File "/home/airflow/.local/lib/python3.7/site-packages/airflow/models/dagbag.py", line 470, in _bag_dag
    check_cycle(dag)  # throws if a task cycle is found
  File "/home/airflow/.local/lib/python3.7/site-packages/airflow/utils/dag_cycle_tester.py", line 78, in check_cycle
    child_to_check = _check_adjacent_tasks(current_task_id, task)
  File "/home/airflow/.local/lib/python3.7/site-packages/airflow/utils/dag_cycle_tester.py", line 64, in _check_adjacent_tasks
    raise AirflowDagCycleException(msg)
airflow.exceptions.AirflowDagCycleException: Cycle detected in DAG: load-data. Faulty task: create_shipment_deliveries
[2023-06-17T14:10:00.416+0000] {processor.py:838} WARNING - No viable dags retrieved from /opt/airflow/dags/sql/load_dag.py
[2023-06-17T14:10:00.549+0000] {processor.py:179} INFO - Processing /opt/airflow/dags/sql/load_dag.py took 0.444 seconds
[2023-06-17T14:11:29.447+0000] {processor.py:157} INFO - Started process (PID=160) to work on /opt/airflow/dags/sql/load_dag.py
[2023-06-17T14:11:32.262+0000] {processor.py:826} INFO - Processing file /opt/airflow/dags/sql/load_dag.py for tasks to queue
[2023-06-17T14:11:32.264+0000] {logging_mixin.py:149} INFO - [2023-06-17T14:11:32.263+0000] {dagbag.py:541} INFO - Filling up the DagBag from /opt/airflow/dags/sql/load_dag.py
[2023-06-17T14:11:32.810+0000] {logging_mixin.py:149} INFO - [2023-06-17T14:11:32.807+0000] {dagbag.py:447} ERROR - Failed to bag_dag: /opt/airflow/dags/sql/load_dag.py
Traceback (most recent call last):
  File "/home/airflow/.local/lib/python3.7/site-packages/airflow/models/dagbag.py", line 445, in _process_modules
    self.bag_dag(dag=dag, root_dag=dag)
  File "/home/airflow/.local/lib/python3.7/site-packages/airflow/models/dagbag.py", line 462, in bag_dag
    self._bag_dag(dag=dag, root_dag=root_dag, recursive=True)
  File "/home/airflow/.local/lib/python3.7/site-packages/airflow/models/dagbag.py", line 470, in _bag_dag
    check_cycle(dag)  # throws if a task cycle is found
  File "/home/airflow/.local/lib/python3.7/site-packages/airflow/utils/dag_cycle_tester.py", line 78, in check_cycle
    child_to_check = _check_adjacent_tasks(current_task_id, task)
  File "/home/airflow/.local/lib/python3.7/site-packages/airflow/utils/dag_cycle_tester.py", line 64, in _check_adjacent_tasks
    raise AirflowDagCycleException(msg)
airflow.exceptions.AirflowDagCycleException: Cycle detected in DAG: load-data. Faulty task: create_shipment_deliveries
[2023-06-17T14:11:32.810+0000] {processor.py:838} WARNING - No viable dags retrieved from /opt/airflow/dags/sql/load_dag.py
[2023-06-17T14:15:37.537+0000] {processor.py:157} INFO - Started process (PID=48) to work on /opt/airflow/dags/sql/load_dag.py
[2023-06-17T14:15:37.616+0000] {processor.py:826} INFO - Processing file /opt/airflow/dags/sql/load_dag.py for tasks to queue
[2023-06-17T14:15:37.619+0000] {logging_mixin.py:149} INFO - [2023-06-17T14:15:37.619+0000] {dagbag.py:541} INFO - Filling up the DagBag from /opt/airflow/dags/sql/load_dag.py
[2023-06-17T14:15:38.276+0000] {logging_mixin.py:149} INFO - [2023-06-17T14:15:38.156+0000] {dagbag.py:447} ERROR - Failed to bag_dag: /opt/airflow/dags/sql/load_dag.py
Traceback (most recent call last):
  File "/home/airflow/.local/lib/python3.7/site-packages/airflow/models/dagbag.py", line 445, in _process_modules
    self.bag_dag(dag=dag, root_dag=dag)
  File "/home/airflow/.local/lib/python3.7/site-packages/airflow/models/dagbag.py", line 462, in bag_dag
    self._bag_dag(dag=dag, root_dag=root_dag, recursive=True)
  File "/home/airflow/.local/lib/python3.7/site-packages/airflow/models/dagbag.py", line 470, in _bag_dag
    check_cycle(dag)  # throws if a task cycle is found
  File "/home/airflow/.local/lib/python3.7/site-packages/airflow/utils/dag_cycle_tester.py", line 78, in check_cycle
    child_to_check = _check_adjacent_tasks(current_task_id, task)
  File "/home/airflow/.local/lib/python3.7/site-packages/airflow/utils/dag_cycle_tester.py", line 64, in _check_adjacent_tasks
    raise AirflowDagCycleException(msg)
airflow.exceptions.AirflowDagCycleException: Cycle detected in DAG: load-data. Faulty task: create_shipment_deliveries
[2023-06-17T14:15:38.277+0000] {processor.py:838} WARNING - No viable dags retrieved from /opt/airflow/dags/sql/load_dag.py
[2023-06-17T14:15:38.526+0000] {processor.py:179} INFO - Processing /opt/airflow/dags/sql/load_dag.py took 0.992 seconds
[2023-06-17T14:16:24.162+0000] {processor.py:157} INFO - Started process (PID=123) to work on /opt/airflow/dags/sql/load_dag.py
[2023-06-17T14:16:24.232+0000] {processor.py:826} INFO - Processing file /opt/airflow/dags/sql/load_dag.py for tasks to queue
[2023-06-17T14:16:24.236+0000] {logging_mixin.py:149} INFO - [2023-06-17T14:16:24.235+0000] {dagbag.py:541} INFO - Filling up the DagBag from /opt/airflow/dags/sql/load_dag.py
[2023-06-17T14:16:24.506+0000] {logging_mixin.py:149} INFO - [2023-06-17T14:16:24.476+0000] {dagbag.py:447} ERROR - Failed to bag_dag: /opt/airflow/dags/sql/load_dag.py
Traceback (most recent call last):
  File "/home/airflow/.local/lib/python3.7/site-packages/airflow/models/dagbag.py", line 445, in _process_modules
    self.bag_dag(dag=dag, root_dag=dag)
  File "/home/airflow/.local/lib/python3.7/site-packages/airflow/models/dagbag.py", line 462, in bag_dag
    self._bag_dag(dag=dag, root_dag=root_dag, recursive=True)
  File "/home/airflow/.local/lib/python3.7/site-packages/airflow/models/dagbag.py", line 470, in _bag_dag
    check_cycle(dag)  # throws if a task cycle is found
  File "/home/airflow/.local/lib/python3.7/site-packages/airflow/utils/dag_cycle_tester.py", line 78, in check_cycle
    child_to_check = _check_adjacent_tasks(current_task_id, task)
  File "/home/airflow/.local/lib/python3.7/site-packages/airflow/utils/dag_cycle_tester.py", line 64, in _check_adjacent_tasks
    raise AirflowDagCycleException(msg)
airflow.exceptions.AirflowDagCycleException: Cycle detected in DAG: load-data. Faulty task: create_shipment_deliveries
[2023-06-17T14:16:24.506+0000] {processor.py:838} WARNING - No viable dags retrieved from /opt/airflow/dags/sql/load_dag.py
[2023-06-17T14:16:24.634+0000] {processor.py:179} INFO - Processing /opt/airflow/dags/sql/load_dag.py took 0.478 seconds
[2023-06-17T14:16:55.339+0000] {processor.py:157} INFO - Started process (PID=187) to work on /opt/airflow/dags/sql/load_dag.py
[2023-06-17T14:16:55.341+0000] {processor.py:826} INFO - Processing file /opt/airflow/dags/sql/load_dag.py for tasks to queue
[2023-06-17T14:16:55.342+0000] {logging_mixin.py:149} INFO - [2023-06-17T14:16:55.342+0000] {dagbag.py:541} INFO - Filling up the DagBag from /opt/airflow/dags/sql/load_dag.py
[2023-06-17T14:16:55.355+0000] {logging_mixin.py:149} INFO - [2023-06-17T14:16:55.354+0000] {dagbag.py:447} ERROR - Failed to bag_dag: /opt/airflow/dags/sql/load_dag.py
Traceback (most recent call last):
  File "/home/airflow/.local/lib/python3.7/site-packages/airflow/models/dagbag.py", line 445, in _process_modules
    self.bag_dag(dag=dag, root_dag=dag)
  File "/home/airflow/.local/lib/python3.7/site-packages/airflow/models/dagbag.py", line 462, in bag_dag
    self._bag_dag(dag=dag, root_dag=root_dag, recursive=True)
  File "/home/airflow/.local/lib/python3.7/site-packages/airflow/models/dagbag.py", line 470, in _bag_dag
    check_cycle(dag)  # throws if a task cycle is found
  File "/home/airflow/.local/lib/python3.7/site-packages/airflow/utils/dag_cycle_tester.py", line 78, in check_cycle
    child_to_check = _check_adjacent_tasks(current_task_id, task)
  File "/home/airflow/.local/lib/python3.7/site-packages/airflow/utils/dag_cycle_tester.py", line 64, in _check_adjacent_tasks
    raise AirflowDagCycleException(msg)
airflow.exceptions.AirflowDagCycleException: Cycle detected in DAG: load-data. Faulty task: create_shipment_deliveries
[2023-06-17T14:16:55.356+0000] {processor.py:838} WARNING - No viable dags retrieved from /opt/airflow/dags/sql/load_dag.py
[2023-06-17T14:16:55.402+0000] {processor.py:179} INFO - Processing /opt/airflow/dags/sql/load_dag.py took 0.073 seconds
