[2023-06-19T04:15:28.171+0000] {processor.py:157} INFO - Started process (PID=55) to work on /opt/airflow/dags/sql/load_dag.py
[2023-06-19T04:15:28.172+0000] {processor.py:826} INFO - Processing file /opt/airflow/dags/sql/load_dag.py for tasks to queue
[2023-06-19T04:15:28.174+0000] {logging_mixin.py:149} INFO - [2023-06-19T04:15:28.174+0000] {dagbag.py:541} INFO - Filling up the DagBag from /opt/airflow/dags/sql/load_dag.py
[2023-06-19T04:15:29.710+0000] {logging_mixin.py:149} INFO - [2023-06-19T04:15:29.667+0000] {dagbag.py:447} ERROR - Failed to bag_dag: /opt/airflow/dags/sql/load_dag.py
Traceback (most recent call last):
  File "/home/airflow/.local/lib/python3.7/site-packages/airflow/models/dagbag.py", line 445, in _process_modules
    self.bag_dag(dag=dag, root_dag=dag)
  File "/home/airflow/.local/lib/python3.7/site-packages/airflow/models/dagbag.py", line 462, in bag_dag
    self._bag_dag(dag=dag, root_dag=root_dag, recursive=True)
  File "/home/airflow/.local/lib/python3.7/site-packages/airflow/models/dagbag.py", line 470, in _bag_dag
    check_cycle(dag)  # throws if a task cycle is found
  File "/home/airflow/.local/lib/python3.7/site-packages/airflow/utils/dag_cycle_tester.py", line 78, in check_cycle
    child_to_check = _check_adjacent_tasks(current_task_id, task)
  File "/home/airflow/.local/lib/python3.7/site-packages/airflow/utils/dag_cycle_tester.py", line 64, in _check_adjacent_tasks
    raise AirflowDagCycleException(msg)
airflow.exceptions.AirflowDagCycleException: Cycle detected in DAG: load-data. Faulty task: create_shipment_deliveries
[2023-06-19T04:15:29.711+0000] {processor.py:838} WARNING - No viable dags retrieved from /opt/airflow/dags/sql/load_dag.py
[2023-06-19T04:15:29.858+0000] {processor.py:179} INFO - Processing /opt/airflow/dags/sql/load_dag.py took 1.693 seconds
[2023-06-19T04:16:41.176+0000] {processor.py:157} INFO - Started process (PID=129) to work on /opt/airflow/dags/sql/load_dag.py
[2023-06-19T04:16:41.179+0000] {processor.py:826} INFO - Processing file /opt/airflow/dags/sql/load_dag.py for tasks to queue
[2023-06-19T04:16:41.182+0000] {logging_mixin.py:149} INFO - [2023-06-19T04:16:41.181+0000] {dagbag.py:541} INFO - Filling up the DagBag from /opt/airflow/dags/sql/load_dag.py
[2023-06-19T04:16:41.962+0000] {logging_mixin.py:149} INFO - [2023-06-19T04:16:41.804+0000] {dagbag.py:447} ERROR - Failed to bag_dag: /opt/airflow/dags/sql/load_dag.py
Traceback (most recent call last):
  File "/home/airflow/.local/lib/python3.7/site-packages/airflow/models/dagbag.py", line 445, in _process_modules
    self.bag_dag(dag=dag, root_dag=dag)
  File "/home/airflow/.local/lib/python3.7/site-packages/airflow/models/dagbag.py", line 462, in bag_dag
    self._bag_dag(dag=dag, root_dag=root_dag, recursive=True)
  File "/home/airflow/.local/lib/python3.7/site-packages/airflow/models/dagbag.py", line 470, in _bag_dag
    check_cycle(dag)  # throws if a task cycle is found
  File "/home/airflow/.local/lib/python3.7/site-packages/airflow/utils/dag_cycle_tester.py", line 78, in check_cycle
    child_to_check = _check_adjacent_tasks(current_task_id, task)
  File "/home/airflow/.local/lib/python3.7/site-packages/airflow/utils/dag_cycle_tester.py", line 64, in _check_adjacent_tasks
    raise AirflowDagCycleException(msg)
airflow.exceptions.AirflowDagCycleException: Cycle detected in DAG: load-data. Faulty task: create_shipment_deliveries
[2023-06-19T04:16:41.963+0000] {processor.py:838} WARNING - No viable dags retrieved from /opt/airflow/dags/sql/load_dag.py
[2023-06-19T04:16:42.265+0000] {processor.py:179} INFO - Processing /opt/airflow/dags/sql/load_dag.py took 1.102 seconds
[2023-06-19T04:17:47.315+0000] {processor.py:157} INFO - Started process (PID=158) to work on /opt/airflow/dags/sql/load_dag.py
[2023-06-19T04:17:47.317+0000] {processor.py:826} INFO - Processing file /opt/airflow/dags/sql/load_dag.py for tasks to queue
[2023-06-19T04:17:47.319+0000] {logging_mixin.py:149} INFO - [2023-06-19T04:17:47.318+0000] {dagbag.py:541} INFO - Filling up the DagBag from /opt/airflow/dags/sql/load_dag.py
[2023-06-19T04:17:47.516+0000] {logging_mixin.py:149} INFO - [2023-06-19T04:17:47.495+0000] {dagbag.py:447} ERROR - Failed to bag_dag: /opt/airflow/dags/sql/load_dag.py
Traceback (most recent call last):
  File "/home/airflow/.local/lib/python3.7/site-packages/airflow/models/dagbag.py", line 445, in _process_modules
    self.bag_dag(dag=dag, root_dag=dag)
  File "/home/airflow/.local/lib/python3.7/site-packages/airflow/models/dagbag.py", line 462, in bag_dag
    self._bag_dag(dag=dag, root_dag=root_dag, recursive=True)
  File "/home/airflow/.local/lib/python3.7/site-packages/airflow/models/dagbag.py", line 470, in _bag_dag
    check_cycle(dag)  # throws if a task cycle is found
  File "/home/airflow/.local/lib/python3.7/site-packages/airflow/utils/dag_cycle_tester.py", line 78, in check_cycle
    child_to_check = _check_adjacent_tasks(current_task_id, task)
  File "/home/airflow/.local/lib/python3.7/site-packages/airflow/utils/dag_cycle_tester.py", line 64, in _check_adjacent_tasks
    raise AirflowDagCycleException(msg)
airflow.exceptions.AirflowDagCycleException: Cycle detected in DAG: load-data. Faulty task: create_shipment_deliveries
[2023-06-19T04:17:47.517+0000] {processor.py:838} WARNING - No viable dags retrieved from /opt/airflow/dags/sql/load_dag.py
[2023-06-19T04:17:47.655+0000] {processor.py:179} INFO - Processing /opt/airflow/dags/sql/load_dag.py took 0.348 seconds
[2023-06-19T04:18:17.694+0000] {processor.py:157} INFO - Started process (PID=225) to work on /opt/airflow/dags/sql/load_dag.py
[2023-06-19T04:18:17.696+0000] {processor.py:826} INFO - Processing file /opt/airflow/dags/sql/load_dag.py for tasks to queue
[2023-06-19T04:18:17.697+0000] {logging_mixin.py:149} INFO - [2023-06-19T04:18:17.696+0000] {dagbag.py:541} INFO - Filling up the DagBag from /opt/airflow/dags/sql/load_dag.py
[2023-06-19T04:18:17.709+0000] {logging_mixin.py:149} INFO - [2023-06-19T04:18:17.708+0000] {dagbag.py:447} ERROR - Failed to bag_dag: /opt/airflow/dags/sql/load_dag.py
Traceback (most recent call last):
  File "/home/airflow/.local/lib/python3.7/site-packages/airflow/models/dagbag.py", line 445, in _process_modules
    self.bag_dag(dag=dag, root_dag=dag)
  File "/home/airflow/.local/lib/python3.7/site-packages/airflow/models/dagbag.py", line 462, in bag_dag
    self._bag_dag(dag=dag, root_dag=root_dag, recursive=True)
  File "/home/airflow/.local/lib/python3.7/site-packages/airflow/models/dagbag.py", line 470, in _bag_dag
    check_cycle(dag)  # throws if a task cycle is found
  File "/home/airflow/.local/lib/python3.7/site-packages/airflow/utils/dag_cycle_tester.py", line 78, in check_cycle
    child_to_check = _check_adjacent_tasks(current_task_id, task)
  File "/home/airflow/.local/lib/python3.7/site-packages/airflow/utils/dag_cycle_tester.py", line 64, in _check_adjacent_tasks
    raise AirflowDagCycleException(msg)
airflow.exceptions.AirflowDagCycleException: Cycle detected in DAG: load-data. Faulty task: create_shipment_deliveries
[2023-06-19T04:18:17.709+0000] {processor.py:838} WARNING - No viable dags retrieved from /opt/airflow/dags/sql/load_dag.py
[2023-06-19T04:18:17.775+0000] {processor.py:179} INFO - Processing /opt/airflow/dags/sql/load_dag.py took 0.085 seconds
[2023-06-19T04:18:48.010+0000] {processor.py:157} INFO - Started process (PID=290) to work on /opt/airflow/dags/sql/load_dag.py
[2023-06-19T04:18:48.011+0000] {processor.py:826} INFO - Processing file /opt/airflow/dags/sql/load_dag.py for tasks to queue
[2023-06-19T04:18:48.012+0000] {logging_mixin.py:149} INFO - [2023-06-19T04:18:48.012+0000] {dagbag.py:541} INFO - Filling up the DagBag from /opt/airflow/dags/sql/load_dag.py
[2023-06-19T04:18:48.023+0000] {logging_mixin.py:149} INFO - [2023-06-19T04:18:48.022+0000] {dagbag.py:447} ERROR - Failed to bag_dag: /opt/airflow/dags/sql/load_dag.py
Traceback (most recent call last):
  File "/home/airflow/.local/lib/python3.7/site-packages/airflow/models/dagbag.py", line 445, in _process_modules
    self.bag_dag(dag=dag, root_dag=dag)
  File "/home/airflow/.local/lib/python3.7/site-packages/airflow/models/dagbag.py", line 462, in bag_dag
    self._bag_dag(dag=dag, root_dag=root_dag, recursive=True)
  File "/home/airflow/.local/lib/python3.7/site-packages/airflow/models/dagbag.py", line 470, in _bag_dag
    check_cycle(dag)  # throws if a task cycle is found
  File "/home/airflow/.local/lib/python3.7/site-packages/airflow/utils/dag_cycle_tester.py", line 78, in check_cycle
    child_to_check = _check_adjacent_tasks(current_task_id, task)
  File "/home/airflow/.local/lib/python3.7/site-packages/airflow/utils/dag_cycle_tester.py", line 64, in _check_adjacent_tasks
    raise AirflowDagCycleException(msg)
airflow.exceptions.AirflowDagCycleException: Cycle detected in DAG: load-data. Faulty task: create_shipment_deliveries
[2023-06-19T04:18:48.024+0000] {processor.py:838} WARNING - No viable dags retrieved from /opt/airflow/dags/sql/load_dag.py
[2023-06-19T04:18:48.139+0000] {processor.py:179} INFO - Processing /opt/airflow/dags/sql/load_dag.py took 0.133 seconds
[2023-06-19T18:42:57.640+0000] {processor.py:157} INFO - Started process (PID=46) to work on /opt/airflow/dags/sql/load_dag.py
[2023-06-19T18:42:57.691+0000] {processor.py:826} INFO - Processing file /opt/airflow/dags/sql/load_dag.py for tasks to queue
[2023-06-19T18:42:57.692+0000] {logging_mixin.py:149} INFO - [2023-06-19T18:42:57.691+0000] {dagbag.py:541} INFO - Filling up the DagBag from /opt/airflow/dags/sql/load_dag.py
[2023-06-19T18:42:57.927+0000] {logging_mixin.py:149} INFO - [2023-06-19T18:42:57.914+0000] {dagbag.py:447} ERROR - Failed to bag_dag: /opt/airflow/dags/sql/load_dag.py
Traceback (most recent call last):
  File "/home/airflow/.local/lib/python3.7/site-packages/airflow/models/dagbag.py", line 445, in _process_modules
    self.bag_dag(dag=dag, root_dag=dag)
  File "/home/airflow/.local/lib/python3.7/site-packages/airflow/models/dagbag.py", line 462, in bag_dag
    self._bag_dag(dag=dag, root_dag=root_dag, recursive=True)
  File "/home/airflow/.local/lib/python3.7/site-packages/airflow/models/dagbag.py", line 470, in _bag_dag
    check_cycle(dag)  # throws if a task cycle is found
  File "/home/airflow/.local/lib/python3.7/site-packages/airflow/utils/dag_cycle_tester.py", line 78, in check_cycle
    child_to_check = _check_adjacent_tasks(current_task_id, task)
  File "/home/airflow/.local/lib/python3.7/site-packages/airflow/utils/dag_cycle_tester.py", line 64, in _check_adjacent_tasks
    raise AirflowDagCycleException(msg)
airflow.exceptions.AirflowDagCycleException: Cycle detected in DAG: load-data. Faulty task: create_shipment_deliveries
[2023-06-19T18:42:57.928+0000] {processor.py:838} WARNING - No viable dags retrieved from /opt/airflow/dags/sql/load_dag.py
[2023-06-19T18:42:57.990+0000] {processor.py:179} INFO - Processing /opt/airflow/dags/sql/load_dag.py took 0.354 seconds
[2023-06-19T18:44:08.776+0000] {processor.py:157} INFO - Started process (PID=120) to work on /opt/airflow/dags/sql/load_dag.py
[2023-06-19T18:44:08.887+0000] {processor.py:826} INFO - Processing file /opt/airflow/dags/sql/load_dag.py for tasks to queue
[2023-06-19T18:44:08.891+0000] {logging_mixin.py:149} INFO - [2023-06-19T18:44:08.890+0000] {dagbag.py:541} INFO - Filling up the DagBag from /opt/airflow/dags/sql/load_dag.py
[2023-06-19T18:44:10.473+0000] {logging_mixin.py:149} INFO - [2023-06-19T18:44:10.417+0000] {dagbag.py:447} ERROR - Failed to bag_dag: /opt/airflow/dags/sql/load_dag.py
Traceback (most recent call last):
  File "/home/airflow/.local/lib/python3.7/site-packages/airflow/models/dagbag.py", line 445, in _process_modules
    self.bag_dag(dag=dag, root_dag=dag)
  File "/home/airflow/.local/lib/python3.7/site-packages/airflow/models/dagbag.py", line 462, in bag_dag
    self._bag_dag(dag=dag, root_dag=root_dag, recursive=True)
  File "/home/airflow/.local/lib/python3.7/site-packages/airflow/models/dagbag.py", line 470, in _bag_dag
    check_cycle(dag)  # throws if a task cycle is found
  File "/home/airflow/.local/lib/python3.7/site-packages/airflow/utils/dag_cycle_tester.py", line 78, in check_cycle
    child_to_check = _check_adjacent_tasks(current_task_id, task)
  File "/home/airflow/.local/lib/python3.7/site-packages/airflow/utils/dag_cycle_tester.py", line 64, in _check_adjacent_tasks
    raise AirflowDagCycleException(msg)
airflow.exceptions.AirflowDagCycleException: Cycle detected in DAG: load-data. Faulty task: create_shipment_deliveries
[2023-06-19T18:44:10.474+0000] {processor.py:838} WARNING - No viable dags retrieved from /opt/airflow/dags/sql/load_dag.py
[2023-06-19T18:44:10.947+0000] {processor.py:179} INFO - Processing /opt/airflow/dags/sql/load_dag.py took 2.181 seconds
[2023-06-19T18:45:13.441+0000] {processor.py:157} INFO - Started process (PID=152) to work on /opt/airflow/dags/sql/load_dag.py
[2023-06-19T18:45:13.497+0000] {processor.py:826} INFO - Processing file /opt/airflow/dags/sql/load_dag.py for tasks to queue
[2023-06-19T18:45:13.500+0000] {logging_mixin.py:149} INFO - [2023-06-19T18:45:13.500+0000] {dagbag.py:541} INFO - Filling up the DagBag from /opt/airflow/dags/sql/load_dag.py
[2023-06-19T18:45:13.603+0000] {logging_mixin.py:149} INFO - [2023-06-19T18:45:13.567+0000] {dagbag.py:447} ERROR - Failed to bag_dag: /opt/airflow/dags/sql/load_dag.py
Traceback (most recent call last):
  File "/home/airflow/.local/lib/python3.7/site-packages/airflow/models/dagbag.py", line 445, in _process_modules
    self.bag_dag(dag=dag, root_dag=dag)
  File "/home/airflow/.local/lib/python3.7/site-packages/airflow/models/dagbag.py", line 462, in bag_dag
    self._bag_dag(dag=dag, root_dag=root_dag, recursive=True)
  File "/home/airflow/.local/lib/python3.7/site-packages/airflow/models/dagbag.py", line 470, in _bag_dag
    check_cycle(dag)  # throws if a task cycle is found
  File "/home/airflow/.local/lib/python3.7/site-packages/airflow/utils/dag_cycle_tester.py", line 78, in check_cycle
    child_to_check = _check_adjacent_tasks(current_task_id, task)
  File "/home/airflow/.local/lib/python3.7/site-packages/airflow/utils/dag_cycle_tester.py", line 64, in _check_adjacent_tasks
    raise AirflowDagCycleException(msg)
airflow.exceptions.AirflowDagCycleException: Cycle detected in DAG: load-data. Faulty task: create_shipment_deliveries
[2023-06-19T18:45:13.604+0000] {processor.py:838} WARNING - No viable dags retrieved from /opt/airflow/dags/sql/load_dag.py
[2023-06-19T18:45:13.724+0000] {processor.py:179} INFO - Processing /opt/airflow/dags/sql/load_dag.py took 0.292 seconds
[2023-06-19T18:45:44.101+0000] {processor.py:157} INFO - Started process (PID=219) to work on /opt/airflow/dags/sql/load_dag.py
[2023-06-19T18:45:44.143+0000] {processor.py:826} INFO - Processing file /opt/airflow/dags/sql/load_dag.py for tasks to queue
[2023-06-19T18:45:44.145+0000] {logging_mixin.py:149} INFO - [2023-06-19T18:45:44.145+0000] {dagbag.py:541} INFO - Filling up the DagBag from /opt/airflow/dags/sql/load_dag.py
[2023-06-19T18:45:44.171+0000] {logging_mixin.py:149} INFO - [2023-06-19T18:45:44.169+0000] {dagbag.py:447} ERROR - Failed to bag_dag: /opt/airflow/dags/sql/load_dag.py
Traceback (most recent call last):
  File "/home/airflow/.local/lib/python3.7/site-packages/airflow/models/dagbag.py", line 445, in _process_modules
    self.bag_dag(dag=dag, root_dag=dag)
  File "/home/airflow/.local/lib/python3.7/site-packages/airflow/models/dagbag.py", line 462, in bag_dag
    self._bag_dag(dag=dag, root_dag=root_dag, recursive=True)
  File "/home/airflow/.local/lib/python3.7/site-packages/airflow/models/dagbag.py", line 470, in _bag_dag
    check_cycle(dag)  # throws if a task cycle is found
  File "/home/airflow/.local/lib/python3.7/site-packages/airflow/utils/dag_cycle_tester.py", line 78, in check_cycle
    child_to_check = _check_adjacent_tasks(current_task_id, task)
  File "/home/airflow/.local/lib/python3.7/site-packages/airflow/utils/dag_cycle_tester.py", line 64, in _check_adjacent_tasks
    raise AirflowDagCycleException(msg)
airflow.exceptions.AirflowDagCycleException: Cycle detected in DAG: load-data. Faulty task: create_shipment_deliveries
[2023-06-19T18:45:44.171+0000] {processor.py:838} WARNING - No viable dags retrieved from /opt/airflow/dags/sql/load_dag.py
[2023-06-19T18:45:44.215+0000] {processor.py:179} INFO - Processing /opt/airflow/dags/sql/load_dag.py took 0.120 seconds
[2023-06-19T18:46:14.503+0000] {processor.py:157} INFO - Started process (PID=287) to work on /opt/airflow/dags/sql/load_dag.py
[2023-06-19T18:46:14.504+0000] {processor.py:826} INFO - Processing file /opt/airflow/dags/sql/load_dag.py for tasks to queue
[2023-06-19T18:46:14.506+0000] {logging_mixin.py:149} INFO - [2023-06-19T18:46:14.506+0000] {dagbag.py:541} INFO - Filling up the DagBag from /opt/airflow/dags/sql/load_dag.py
[2023-06-19T18:46:14.525+0000] {logging_mixin.py:149} INFO - [2023-06-19T18:46:14.524+0000] {dagbag.py:447} ERROR - Failed to bag_dag: /opt/airflow/dags/sql/load_dag.py
Traceback (most recent call last):
  File "/home/airflow/.local/lib/python3.7/site-packages/airflow/models/dagbag.py", line 445, in _process_modules
    self.bag_dag(dag=dag, root_dag=dag)
  File "/home/airflow/.local/lib/python3.7/site-packages/airflow/models/dagbag.py", line 462, in bag_dag
    self._bag_dag(dag=dag, root_dag=root_dag, recursive=True)
  File "/home/airflow/.local/lib/python3.7/site-packages/airflow/models/dagbag.py", line 470, in _bag_dag
    check_cycle(dag)  # throws if a task cycle is found
  File "/home/airflow/.local/lib/python3.7/site-packages/airflow/utils/dag_cycle_tester.py", line 78, in check_cycle
    child_to_check = _check_adjacent_tasks(current_task_id, task)
  File "/home/airflow/.local/lib/python3.7/site-packages/airflow/utils/dag_cycle_tester.py", line 64, in _check_adjacent_tasks
    raise AirflowDagCycleException(msg)
airflow.exceptions.AirflowDagCycleException: Cycle detected in DAG: load-data. Faulty task: create_shipment_deliveries
[2023-06-19T18:46:14.526+0000] {processor.py:838} WARNING - No viable dags retrieved from /opt/airflow/dags/sql/load_dag.py
[2023-06-19T18:46:14.564+0000] {processor.py:179} INFO - Processing /opt/airflow/dags/sql/load_dag.py took 0.070 seconds
[2023-06-19T18:46:44.896+0000] {processor.py:157} INFO - Started process (PID=355) to work on /opt/airflow/dags/sql/load_dag.py
[2023-06-19T18:46:44.941+0000] {processor.py:826} INFO - Processing file /opt/airflow/dags/sql/load_dag.py for tasks to queue
[2023-06-19T18:46:44.942+0000] {logging_mixin.py:149} INFO - [2023-06-19T18:46:44.942+0000] {dagbag.py:541} INFO - Filling up the DagBag from /opt/airflow/dags/sql/load_dag.py
[2023-06-19T18:46:44.953+0000] {logging_mixin.py:149} INFO - [2023-06-19T18:46:44.952+0000] {dagbag.py:447} ERROR - Failed to bag_dag: /opt/airflow/dags/sql/load_dag.py
Traceback (most recent call last):
  File "/home/airflow/.local/lib/python3.7/site-packages/airflow/models/dagbag.py", line 445, in _process_modules
    self.bag_dag(dag=dag, root_dag=dag)
  File "/home/airflow/.local/lib/python3.7/site-packages/airflow/models/dagbag.py", line 462, in bag_dag
    self._bag_dag(dag=dag, root_dag=root_dag, recursive=True)
  File "/home/airflow/.local/lib/python3.7/site-packages/airflow/models/dagbag.py", line 470, in _bag_dag
    check_cycle(dag)  # throws if a task cycle is found
  File "/home/airflow/.local/lib/python3.7/site-packages/airflow/utils/dag_cycle_tester.py", line 78, in check_cycle
    child_to_check = _check_adjacent_tasks(current_task_id, task)
  File "/home/airflow/.local/lib/python3.7/site-packages/airflow/utils/dag_cycle_tester.py", line 64, in _check_adjacent_tasks
    raise AirflowDagCycleException(msg)
airflow.exceptions.AirflowDagCycleException: Cycle detected in DAG: load-data. Faulty task: create_shipment_deliveries
[2023-06-19T18:46:44.954+0000] {processor.py:838} WARNING - No viable dags retrieved from /opt/airflow/dags/sql/load_dag.py
[2023-06-19T18:46:44.991+0000] {processor.py:179} INFO - Processing /opt/airflow/dags/sql/load_dag.py took 0.100 seconds
[2023-06-19T18:47:15.581+0000] {processor.py:157} INFO - Started process (PID=423) to work on /opt/airflow/dags/sql/load_dag.py
[2023-06-19T18:47:15.582+0000] {processor.py:826} INFO - Processing file /opt/airflow/dags/sql/load_dag.py for tasks to queue
[2023-06-19T18:47:15.583+0000] {logging_mixin.py:149} INFO - [2023-06-19T18:47:15.583+0000] {dagbag.py:541} INFO - Filling up the DagBag from /opt/airflow/dags/sql/load_dag.py
[2023-06-19T18:47:15.594+0000] {logging_mixin.py:149} INFO - [2023-06-19T18:47:15.593+0000] {dagbag.py:447} ERROR - Failed to bag_dag: /opt/airflow/dags/sql/load_dag.py
Traceback (most recent call last):
  File "/home/airflow/.local/lib/python3.7/site-packages/airflow/models/dagbag.py", line 445, in _process_modules
    self.bag_dag(dag=dag, root_dag=dag)
  File "/home/airflow/.local/lib/python3.7/site-packages/airflow/models/dagbag.py", line 462, in bag_dag
    self._bag_dag(dag=dag, root_dag=root_dag, recursive=True)
  File "/home/airflow/.local/lib/python3.7/site-packages/airflow/models/dagbag.py", line 470, in _bag_dag
    check_cycle(dag)  # throws if a task cycle is found
  File "/home/airflow/.local/lib/python3.7/site-packages/airflow/utils/dag_cycle_tester.py", line 78, in check_cycle
    child_to_check = _check_adjacent_tasks(current_task_id, task)
  File "/home/airflow/.local/lib/python3.7/site-packages/airflow/utils/dag_cycle_tester.py", line 64, in _check_adjacent_tasks
    raise AirflowDagCycleException(msg)
airflow.exceptions.AirflowDagCycleException: Cycle detected in DAG: load-data. Faulty task: create_shipment_deliveries
[2023-06-19T18:47:15.595+0000] {processor.py:838} WARNING - No viable dags retrieved from /opt/airflow/dags/sql/load_dag.py
[2023-06-19T18:47:15.650+0000] {processor.py:179} INFO - Processing /opt/airflow/dags/sql/load_dag.py took 0.075 seconds
[2023-06-19T18:47:45.814+0000] {processor.py:157} INFO - Started process (PID=491) to work on /opt/airflow/dags/sql/load_dag.py
[2023-06-19T18:47:45.816+0000] {processor.py:826} INFO - Processing file /opt/airflow/dags/sql/load_dag.py for tasks to queue
[2023-06-19T18:47:45.817+0000] {logging_mixin.py:149} INFO - [2023-06-19T18:47:45.816+0000] {dagbag.py:541} INFO - Filling up the DagBag from /opt/airflow/dags/sql/load_dag.py
[2023-06-19T18:47:45.828+0000] {logging_mixin.py:149} INFO - [2023-06-19T18:47:45.827+0000] {dagbag.py:447} ERROR - Failed to bag_dag: /opt/airflow/dags/sql/load_dag.py
Traceback (most recent call last):
  File "/home/airflow/.local/lib/python3.7/site-packages/airflow/models/dagbag.py", line 445, in _process_modules
    self.bag_dag(dag=dag, root_dag=dag)
  File "/home/airflow/.local/lib/python3.7/site-packages/airflow/models/dagbag.py", line 462, in bag_dag
    self._bag_dag(dag=dag, root_dag=root_dag, recursive=True)
  File "/home/airflow/.local/lib/python3.7/site-packages/airflow/models/dagbag.py", line 470, in _bag_dag
    check_cycle(dag)  # throws if a task cycle is found
  File "/home/airflow/.local/lib/python3.7/site-packages/airflow/utils/dag_cycle_tester.py", line 78, in check_cycle
    child_to_check = _check_adjacent_tasks(current_task_id, task)
  File "/home/airflow/.local/lib/python3.7/site-packages/airflow/utils/dag_cycle_tester.py", line 64, in _check_adjacent_tasks
    raise AirflowDagCycleException(msg)
airflow.exceptions.AirflowDagCycleException: Cycle detected in DAG: load-data. Faulty task: create_shipment_deliveries
[2023-06-19T18:47:45.829+0000] {processor.py:838} WARNING - No viable dags retrieved from /opt/airflow/dags/sql/load_dag.py
[2023-06-19T18:47:45.855+0000] {processor.py:179} INFO - Processing /opt/airflow/dags/sql/load_dag.py took 0.047 seconds
